Workbook

Sheet Início
B2: Let's Go ✈ — Financeiro
B3: Confidencial · só a gestão 🔒
B5: Ligação ao operacional
B6: • A aba «Importar Reservas» recebe o que a equipa insere no ficheiro operacional.
B7: • No Google Sheets, cola na célula A3 dessa aba:
B8: • =IMPORTRANGE(Configurações!B17; "Reservas!A2:AF")
B9: • Na 1.ª vez o Sheets pede «Permitir acesso». É uma ligação de sentido único (só lê).
B11: O que este ficheiro faz 💰
B12: • Comissões por funcionário (confidencial) · Custos fixos · Fluxo de caixa.
B13: • Contas a receber · Lucros (P&L) · Dashboard. O custo usado é o custo TOTAL de fornecedores da reserva.

Sheet Configurações
A1: ⚙️ Configurações (confidencial)
A2: Regras de comissão, câmbios e definições. Mudar aqui altera os cálculos sem mexer em fórmulas.
A3: Comissões por funcionário | E3: Câmbios (→ EUR)
A4: Moeda | B4: Câmbio p/ EUR | C4: Base de cálculo | E4: Moeda | F4: Câmbio p/ EUR
A5: Sofia | B5: 0.05 | C5: Margem | E5: EUR | F5: 1
A6: Miguel | B6: 0.04 | C6: Margem | E6: USD | F6: 0.92
E7: GBP | F7: 1.17
A8: Base «Margem» = venda − custo total dos fornecedores. | E8: BRL | F8: 0.18
E10: Atualizar à mão quando necessário.
A11: Definições / notas
A12: • Regime de IVA: confirmar com a contabilista (agências costumam usar o regime de margem).
A13: • Custos fixos: ver aba «Custos Fixos». Gastos avulsos: ver aba «Gastos Adicionais».
A15: Integração e período | B15: Valor
A16: Ano do relatório | B16: 2026
A17: URL da planilha Operacional | B17: COLAR_URL_AQUI
A18: Saldo inicial de caixa (€) | B18: 2000

Sheet Importar Reservas
A1: SINCRONIZAÇÃO: em Google Sheets, apaga os exemplos A3:AF e usa em A3: =IMPORTRANGE(Configurações!B17;"Reservas!A2:AF") — depois clica Permitir acesso.
A2: ID Reserva | B2: Data registo | C2: ID Cliente | D2: Cliente | E2: ID Pacote | F2: Pacote | G2: Tipo | H2: Destino | I2: Data início | J2: Data fim | K2: Nº pax | L2: Estado | M2: Estado aprovação | N2: Custo total (€) | O2: Valor venda (€) | P2: Margem (€) | Q2: Aprovado por | R2: Tipo pagamento | S2: Nº prestações | T2: Prestações pagas | U2: Valor/prestação (€) | V2: Valor pago (€) | W2: Valor pendente (€) | X2: Prestações em falta | Y2: % pago | Z2: Vendedor | AA2: Criado por | AB2: Motivo | AC2: Contactado? | AD2: Próxima ação | AE2: Data follow-up | AF2: Observações
A3: R-2026-001 | B3: 46063 | C3: C-001 | D3: João Silva | E3: P-001 | F3: Réveillon Madeira 2026 | G3: Grupo | H3: Funchal, Madeira | I3: 46384 | J3: 46388 | K3: 2 | L3: Confirmada | M3: Aprovado | N3: 1180 | O3: 1720 | P3: 540 | Q3: Gestora | R3: A prestações | S3: 4 | T3: 1 | U3: 430 | V3: 430 | W3: 1290 | X3: 3 | Y3: 0.25 | Z3: Sofia | AA3: Sofia
A4: R-2026-002 | B4: 46071 | C4: C-002 | D4: Maria Santos | E4: P-003 | F4: Lua de Mel Maldivas | G4: Exclusivo | H4: Maldivas | I4: 46188 | J4: 46198 | K4: 2 | L4: Paga | M4: Aprovado | N4: 6900 | O4: 8400 | P4: 1500 | Q4: Gestora | R4: A pronto | S4: 1 | T4: 1 | U4: 8400 | V4: 8400 | W4: 0 | X4: 0 | Y4: 1 | Z4: Sofia | AA4: Sofia
A5: R-2026-003 | B5: 46083 | C5: C-003 | D5: Pedro Costa | E5: P-004 | F5: City Break Roma | G5: Exclusivo | H5: Roma, Itália | I5: 46122 | J5: 46126 | K5: 2 | L5: Concluída | M5: Aprovado | N5: 890 | O5: 1250 | P5: 360 | Q5: Gestora | R5: A pronto | S5: 1 | T5: 1 | U5: 1250 | V5: 1250 | W5: 0 | X5: 0 | Y5: 1 | Z5: Miguel | AA5: Miguel
A6: R-2026-004 | B6: 46093 | C6: C-004 | D6: Ana Ferreira | E6: P-002 | F6: Peregrinação a Fátima | G6: Grupo | H6: Fátima | I6: 46154 | J6: 46155 | K6: 1 | L6: Documentos recebidos | M6: Aprovado | N6: 95 | O6: 145 | P6: 50 | Q6: Gestora | R6: A pronto | S6: 1 | T6: 1 | U6: 145 | V6: 145 | W6: 0 | X6: 0 | Y6: 1 | Z6: Miguel | AA6: Miguel
A7: R-2026-005 | B7: 46101 | C7: C-005 | D7: Rui Almeida | E7: P-005 | F7: Safari Tanzânia | G7: Exclusivo | H7: Tanzânia | I7: 46239 | J7: 46249 | K7: 4 | L7: Confirmada | M7: Aprovado | N7: 12800 | O7: 15600 | P7: 2800 | Q7: Gestora | R7: A prestações | S7: 6 | T7: 2 | U7: 2600 | V7: 5200 | W7: 10400 | X7: 4 | Y7: 0.33333333 | Z7: Sofia | AA7: Sofia | AF7: Grupo de 4
A8: R-2026-006 | B8: 46113 | C8: C-001 | D8: João Silva | E8: P-001 | F8: Réveillon Madeira 2026 | G8: Grupo | H8: Funchal, Madeira | I8: 46384 | J8: 46388 | K8: 3 | L8: Em orçamento | M8: Aguarda aprovação | N8: 1620 | R8: A prestações | S8: 3 | T8: 0 | X8: 3 | Z8: Sofia | AA8: Sofia | AC8: Não | AD8: Enviar proposta ao cliente | AE8: 46218 | AF8: Aguarda custos dos fornecedores
A9: R-2026-007 | B9: 46117 | C9: C-002 | D9: Maria Santos | E9: P-004 | F9: City Break Roma | G9: Exclusivo | H9: Roma, Itália | I9: 46275 | J9: 46279 | K9: 2 | L9: Cancelada | M9: Recusado | N9: 0 | R9: A pronto | S9: 1 | T9: 0 | X9: 1 | Z9: Miguel | AA9: Miguel | AB9: Preço acima do orçamento do cliente | AC9: Sim | AD9: Reenviar proposta mais económica em setembro | AE9: 46266 | AF9: Cliente quer alternativa mais barata

Sheet Comissões
A1: 💼 Comissões (confidencial)
A3: Regras (taxas) definidas na aba «Configurações».
A9: Cálculo por reserva (puxa de «Importar Reservas»)
A10: ID Reserva | B10: Data | C10: Funcionário | D10: Valor venda (€) | E10: Custo total (€) | F10: Base | G10: Taxa | H10: Comissão (€) | J10: Funcionário | K10: Comissão (€)
A11: =IF('Importar Reservas'!A3="","",'Importar Reservas'!A3) | B11: =IF($A11="","",'Importar Reservas'!B3) | C11: =IF($A11="","",'Importar Reservas'!Z3) | D11: =IF($A11="","",IF('Importar Reservas'!O3="",0,'Importar Reservas'!O3)) | E11: =IF($A11="","",IF('Importar Reservas'!N3="",0,'Importar Reservas'!N3)) | F11: =IF($A11="","",IFERROR(INDEX(Configurações!$C$5:$C$100,MATCH($C11,Configurações!$A$5:$A$100,0)),"Margem")) | G11: =IF($A11="","",IFERROR(INDEX(Configurações!$B$5:$B$100,MATCH($C11,Configurações!$A$5:$A$100,0)),0)) | H11: =IF(OR($A11="",'Importar Reservas'!M3<>"Aprovado",$D11<=0),"",MAX(0,IF($F11="Margem",$D11-$E11,$D11))*$G11) | J11: =IFERROR(_xlfn.unique(_xlfn._xlws.filter(C11:C1009,C11:C1009<>"")),"") | K11: =IF(J11="","",SUMIF(C:C,J11,H:H))
A12: =IF('Importar Reservas'!A4="","",'Importar Reservas'!A4) | B12: =IF($A12="","",'Importar Reservas'!B4) | C12: =IF($A12="","",'Importar Reservas'!Z4) | D12: =IF($A12="","",IF('Importar Reservas'!O4="",0,'Importar Reservas'!O4)) | E12: =IF($A12="","",IF('Importar Reservas'!N4="",0,'Importar Reservas'!N4)) | F12: =IF($A12="","",IFERROR(INDEX(Configurações!$C$5:$C$100,MATCH($C12,Configurações!$A$5:$A$100,0)),"Margem")) | G12: =IF($A12="","",IFERROR(INDEX(Configurações!$B$5:$B$100,MATCH($C12,Configurações!$A$5:$A$100,0)),0)) | H12: =IF(OR($A12="",'Importar Reservas'!M4<>"Aprovado",$D12<=0),"",MAX(0,IF($F12="Margem",$D12-$E12,$D12))*$G12) | K12: =IF(J12="","",SUMIF(C:C,J12,H:H))
A13: =IF('Importar Reservas'!A5="","",'Importar Reservas'!A5) | B13: =IF($A13="","",'Importar Reservas'!B5) | C13: =IF($A13="","",'Importar Reservas'!Z5) | D13: =IF($A13="","",IF('Importar Reservas'!O5="",0,'Importar Reservas'!O5)) | E13: =IF($A13="","",IF('Importar Reservas'!N5="",0,'Importar Reservas'!N5)) | F13: =IF($A13="","",IFERROR(INDEX(Configurações!$C$5:$C$100,MATCH($C13,Configurações!$A$5:$A$100,0)),"Margem")) | G13: =IF($A13="","",IFERROR(INDEX(Configurações!$B$5:$B$100,MATCH($C13,Configurações!$A$5:$A$100,0)),0)) | H13: =IF(OR($A13="",'Importar Reservas'!M5<>"Aprovado",$D13<=0),"",MAX(0,IF($F13="Margem",$D13-$E13,$D13))*$G13) | K13: =IF(J13="","",SUMIF(C:C,J13,H:H))
A14: =IF('Importar Reservas'!A6="","",'Importar Reservas'!A6) | B14: =IF($A14="","",'Importar Reservas'!B6) | C14: =IF($A14="","",'Importar Reservas'!Z6) | D14: =IF($A14="","",IF('Importar Reservas'!O6="",0,'Importar Reservas'!O6)) | E14: =IF($A14="","",IF('Importar Reservas'!N6="",0,'Importar Reservas'!N6)) | F14: =IF($A14="","",IFERROR(INDEX(Configurações!$C$5:$C$100,MATCH($C14,Configurações!$A$5:$A$100,0)),"Margem")) | G14: =IF($A14="","",IFERROR(INDEX(Configurações!$B$5:$B$100,MATCH($C14,Configurações!$A$5:$A$100,0)),0)) | H14: =IF(OR($A14="",'Importar Reservas'!M6<>"Aprovado",$D14<=0),"",MAX(0,IF($F14="Margem",$D14-$E14,$D14))*$G14) | K14: =IF(J14="","",SUMIF(C:C,J14,H:H))
A15: =IF('Importar Reservas'!A7="","",'Importar Reservas'!A7) | B15: =IF($A15="","",'Importar Reservas'!B7) | C15: =IF($A15="","",'Importar Reservas'!Z7) | D15: =IF($A15="","",IF('Importar Reservas'!O7="",0,'Importar Reservas'!O7)) | E15: =IF($A15="","",IF('Importar Reservas'!N7="",0,'Importar Reservas'!N7)) | F15: =IF($A15="","",IFERROR(INDEX(Configurações!$C$5:$C$100,MATCH($C15,Configurações!$A$5:$A$100,0)),"Margem")) | G15: =IF($A15="","",IFERROR(INDEX(Configurações!$B$5:$B$100,MATCH($C15,Configurações!$A$5:$A$100,0)),0)) | H15: =IF(OR($A15="",'Importar Reservas'!M7<>"Aprovado",$D15<=0),"",MAX(0,IF($F15="Margem",$D15-$E15,$D15))*$G15) | K15: =IF(J15="","",SUMIF(C:C,J15,H:H))
A16: =IF('Importar Reservas'!A8="","",'Importar Reservas'!A8) | B16: =IF($A16="","",'Importar Reservas'!B8) | C16: =IF($A16="","",'Importar Reservas'!Z8) | D16: =IF($A16="","",IF('Importar Reservas'!O8="",0,'Importar Reservas'!O8)) | E16: =IF($A16="","",IF('Importar Reservas'!N8="",0,'Importar Reservas'!N8)) | F16: =IF($A16="","",IFERROR(INDEX(Configurações!$C$5:$C$100,MATCH($C16,Configurações!$A$5:$A$100,0)),"Margem")) | G16: =IF($A16="","",IFERROR(INDEX(Configurações!$B$5:$B$100,MATCH($C16,Configurações!$A$5:$A$100,0)),0)) | H16: =IF(OR($A16="",'Importar Reservas'!M8<>"Aprovado",$D16<=0),"",MAX(0,IF($F16="Margem",$D16-$E16,$D16))*$G16) | K16: =IF(J16="","",SUMIF(C:C,J16,H:H))
A17: =IF('Importar Reservas'!A9="","",'Importar Reservas'!A9) | B17: =IF($A17="","",'Importar Reservas'!B9) | C17: =IF($A17="","",'Importar Reservas'!Z9) | D17: =IF($A17="","",IF('Importar Reservas'!O9="",0,'Importar Reservas'!O9)) | E17: =IF($A17="","",IF('Importar Reservas'!N9="",0,'Importar Reservas'!N9)) | F17: =IF($A17="","",IFERROR(INDEX(Configurações!$C$5:$C$100,MATCH($C17,Configurações!$A$5:$A$100,0)),"Margem")) | G17: =IF($A17="","",IFERROR(INDEX(Configurações!$B$5:$B$100,MATCH($C17,Configurações!$A$5:$A$100,0)),0)) | H17: =IF(OR($A17="",'Importar Reservas'!M9<>"Aprovado",$D17<=0),"",MAX(0,IF($F17="Margem",$D17-$E17,$D17))*$G17) | K17: =IF(J17="","",SUMIF(C:C,J17,H:H))
A18: =IF('Importar Reservas'!A10="","",'Importar Reservas'!A10) | B18: =IF($A18="","",'Importar Reservas'!B10) | C18: =IF($A18="","",'Importar Reservas'!Z10) | D18: =IF($A18="","",IF('Importar Reservas'!O10="",0,'Importar Reservas'!O10)) | E18: =IF($A18="","",IF('Importar Reservas'!N10="",0,'Importar Reservas'!N10)) | F18: =IF($A18="","",IFERROR(INDEX(Configurações!$C$5:$C$100,MATCH($C18,Configurações!$A$5:$A$100,0)),"Margem")) | G18: =IF($A18="","",IFERROR(INDEX(Configurações!$B$5:$B$100,MATCH($C18,Configurações!$A$5:$A$100,0)),0)) | H18: =IF(OR($A18="",'Importar Reservas'!M10<>"Aprovado",$D18<=0),"",MAX(0,IF($F18="Margem",$D18-$E18,$D18))*$G18) | K18: =IF(J18="","",SUMIF(C:C,J18,H:H))
A19: =IF('Importar Reservas'!A11="","",'Importar Reservas'!A11) | B19: =IF($A19="","",'Importar Reservas'!B11) | C19: =IF($A19="","",'Importar Reservas'!Z11) | D19: =IF($A19="","",IF('Importar Reservas'!O11="",0,'Importar Reservas'!O11)) | E19: =IF($A19="","",IF('Importar Reservas'!N11="",0,'Importar Reservas'!N11)) | F19: =IF($A19="","",IFERROR(INDEX(Configurações!$C$5:$C$100,MATCH($C19,Configurações!$A$5:$A$100,0)),"Margem")) | G19: =IF($A19="","",IFERROR(INDEX(Configurações!$B$5:$B$100,MATCH($C19,Configurações!$A$5:$A$100,0)),0)) | H19: =IF(OR($A19="",'Importar Reservas'!M11<>"Aprovado",$D19<=0),"",MAX(0,IF($F19="Margem",$D19-$E19,$D19))*$G19) | K19: =IF(J19="","",SUMIF(C:C,J19,H:H))
A20: =IF('Importar Reservas'!A12="","",'Importar Reservas'!A12) | B20: =IF($A20="","",'Importar Reservas'!B12) | C20: =IF($A20="","",'Importar Reservas'!Z12) | D20: =IF($A20="","",IF('Importar Reservas'!O12="",0,'Importar Reservas'!O12)) | E20: =IF($A20="","",IF('Importar Reservas'!N12="",0,'Importar Reservas'!N12)) | F20: =IF($A20="","",IFERROR(INDEX(Configurações!$C$5:$C$100,MATCH($C20,Configurações!$A$5:$A$100,0)),"Margem")) | G20: =IF($A20="","",IFERROR(INDEX(Configurações!$B$5:$B$100,MATCH($C20,Configurações!$A$5:$A$100,0)),0)) | H20: =IF(OR($A20="",'Importar Reservas'!M12<>"Aprovado",$D20<=0),"",MAX(0,IF($F20="Margem",$D20-$E20,$D20))*$G20) | K20: =IF(J20="","",SUMIF(C:C,J20,H:H))
A21: =IF('Importar Reservas'!A13="","",'Importar Reservas'!A13) | B21: =IF($A21="","",'Importar Reservas'!B13) | C21: =IF($A21="","",'Importar Reservas'!Z13) | D21: =IF($A21="","",IF('Importar Reservas'!O13="",0,'Importar Reservas'!O13)) | E21: =IF($A21="","",IF('Importar Reservas'!N13="",0,'Importar Reservas'!N13)) | F21: =IF($A21="","",IFERROR(INDEX(Configurações!$C$5:$C$100,MATCH($C21,Configurações!$A$5:$A$100,0)),"Margem")) | G21: =IF($A21="","",IFERROR(INDEX(Configurações!$B$5:$B$100,MATCH($C21,Configurações!$A$5:$A$100,0)),0)) | H21: =IF(OR($A21="",'Importar Reservas'!M13<>"Aprovado",$D21<=0),"",MAX(0,IF($F21="Margem",$D21-$E21,$D21))*$G21) | K21: =IF(J21="","",SUMIF(C:C,J21,H:H))
A22: =IF('Importar Reservas'!A14="","",'Importar Reservas'!A14) | B22: =IF($A22="","",'Importar Reservas'!B14) | C22: =IF($A22="","",'Importar Reservas'!Z14) | D22: =IF($A22="","",IF('Importar Reservas'!O14="",0,'Importar Reservas'!O14)) | E22: =IF($A22="","",IF('Importar Reservas'!N14="",0,'Importar Reservas'!N14)) | F22: =IF($A22="","",IFERROR(INDEX(Configurações!$C$5:$C$100,MATCH($C22,Configurações!$A$5:$A$100,0)),"Margem")) | G22: =IF($A22="","",IFERROR(INDEX(Configurações!$B$5:$B$100,MATCH($C22,Configurações!$A$5:$A$100,0)),0)) | H22: =IF(OR($A22="",'Importar Reservas'!M14<>"Aprovado",$D22<=0),"",MAX(0,IF($F22="Margem",$D22-$E22,$D22))*$G22) | K22: =IF(J22="","",SUMIF(C:C,J22,H:H))
A23: =IF('Importar Reservas'!A15="","",'Importar Reservas'!A15) | B23: =IF($A23="","",'Importar Reservas'!B15) | C23: =IF($A23="","",'Importar Reservas'!Z15) | D23: =IF($A23="","",IF('Importar Reservas'!O15="",0,'Importar Reservas'!O15)) | E23: =IF($A23="","",IF('Importar Reservas'!N15="",0,'Importar Reservas'!N15)) | F23: =IF($A23="","",IFERROR(INDEX(Configurações!$C$5:$C$100,MATCH($C23,Configurações!$A$5:$A$100,0)),"Margem")) | G23: =IF($A23="","",IFERROR(INDEX(Configurações!$B$5:$B$100,MATCH($C23,Configurações!$A$5:$A$100,0)),0)) | H23: =IF(OR($A23="",'Importar Reservas'!M15<>"Aprovado",$D23<=0),"",MAX(0,IF($F23="Margem",$D23-$E23,$D23))*$G23) | K23: =IF(J23="","",SUMIF(C:C,J23,H:H))
... A100: =IF('Importar Reservas'!A92="","",'Importar Reservas'!A92) | B100: =IF($A100="","",'Importar Reservas'!B92) | C100: =IF($A100="","",'Importar Reservas'!Z92) | D100: =IF($A100="","",IF('Importar Reservas'!O92="",0,'Importar Reservas'!O92)) | E100: =IF($A100="","",IF('Importar Reservas'!N92="",0,'Importar Reservas'!N92)) | F100: =IF($A100="","",IFERROR(INDEX(Configurações!$C$5:$C$100,MATCH($C100,Configurações!$A$5:$A$100,0)),"Margem")) | G100: =IF($A100="","",IFERROR(INDEX(Configurações!$B$5:$B$100,MATCH($C100,Configurações!$A$5:$A$100,0)),0)) | H100: =IF(OR($A100="",'Importar Reservas'!M92<>"Aprovado",$D100<=0),"",MAX(0,IF($F100="Margem",$D100-$E100,$D100))*$G100) | K100: =IF(J100="","",SUMIF(C:C,J100,H:H))
A101: =IF('Importar Reservas'!A93="","",'Importar Reservas'!A93) | B101: =IF($A101="","",'Importar Reservas'!B93) | C101: =IF($A101="","",'Importar Reservas'!Z93) | D101: =IF($A101="","",IF('Importar Reservas'!O93="",0,'Importar Reservas'!O93)) | E101: =IF($A101="","",IF('Importar Reservas'!N93="",0,'Importar Reservas'!N93)) | F101: =IF($A101="","",IFERROR(INDEX(Configurações!$C$5:$C$100,MATCH($C101,Configurações!$A$5:$A$100,0)),"Margem")) | G101: =IF($A101="","",IFERROR(INDEX(Configurações!$B$5:$B$100,MATCH($C101,Configurações!$A$5:$A$100,0)),0)) | H101: =IF(OR($A101="",'Importar Reservas'!M93<>"Aprovado",$D101<=0),"",MAX(0,IF($F101="Margem",$D101-$E101,$D101))*$G101)
A102: =IF('Importar Reservas'!A94="","",'Importar Reservas'!A94) | B102: =IF($A102="","",'Importar Reservas'!B94) | C102: =IF($A102="","",'Importar Reservas'!Z94) | D102: =IF($A102="","",IF('Importar Reservas'!O94="",0,'Importar Reservas'!O94)) | E102: =IF($A102="","",IF('Importar Reservas'!N94="",0,'Importar Reservas'!N94)) | F102: =IF($A102="","",IFERROR(INDEX(Configurações!$C$5:$C$100,MATCH($C102,Configurações!$A$5:$A$100,0)),"Margem")) | G102: =IF($A102="","",IFERROR(INDEX(Configurações!$B$5:$B$100,MATCH($C102,Configurações!$A$5:$A$100,0)),0)) | H102: =IF(OR($A102="",'Importar Reservas'!M94<>"Aprovado",$D102<=0),"",MAX(0,IF($F102="Margem",$D102-$E102,$D102))*$G102)
A103: =IF('Importar Reservas'!A95="","",'Importar Reservas'!A95) | B103: =IF($A103="","",'Importar Reservas'!B95) | C103: =IF($A103="","",'Importar Reservas'!Z95) | D103: =IF($A103="","",IF('Importar Reservas'!O95="",0,'Importar Reservas'!O95)) | E103: =IF($A103="","",IF('Importar Reservas'!N95="",0,'Importar Reservas'!N95)) | F103: =IF($A103="","",IFERROR(INDEX(Configurações!$C$5:$C$100,MATCH($C103,Configurações!$A$5:$A$100,0)),"Margem")) | G103: =IF($A103="","",IFERROR(INDEX(Configurações!$B$5:$B$100,MATCH($C103,Configurações!$A$5:$A$100,0)),0)) | H103: =IF(OR($A103="",'Importar Reservas'!M95<>"Aprovado",$D103<=0),"",MAX(0,IF($F103="Margem",$D103-$E103,$D103))*$G103)
A104: =IF('Importar Reservas'!A96="","",'Importar Reservas'!A96) | B104: =IF($A104="","",'Importar Reservas'!B96) | C104: =IF($A104="","",'Importar Reservas'!Z96) | D104: =IF($A104="","",IF('Importar Reservas'!O96="",0,'Importar Reservas'!O96)) | E104: =IF($A104="","",IF('Importar Reservas'!N96="",0,'Importar Reservas'!N96)) | F104: =IF($A104="","",IFERROR(INDEX(Configurações!$C$5:$C$100,MATCH($C104,Configurações!$A$5:$A$100,0)),"Margem")) | G104: =IF($A104="","",IFERROR(INDEX(Configurações!$B$5:$B$100,MATCH($C104,Configurações!$A$5:$A$100,0)),0)) | H104: =IF(OR($A104="",'Importar Reservas'!M96<>"Aprovado",$D104<=0),"",MAX(0,IF($F104="Margem",$D104-$E104,$D104))*$G104)
A105: =IF('Importar Reservas'!A97="","",'Importar Reservas'!A97) | B105: =IF($A105="","",'Importar Reservas'!B97) | C105: =IF($A105="","",'Importar Reservas'!Z97) | D105: =IF($A105="","",IF('Importar Reservas'!O97="",0,'Importar Reservas'!O97)) | E105: =IF($A105="","",IF('Importar Reservas'!N97="",0,'Importar Reservas'!N97)) | F105: =IF($A105="","",IFERROR(INDEX(Configurações!$C$5:$C$100,MATCH($C105,Configurações!$A$5:$A$100,0)),"Margem")) | G105: =IF($A105="","",IFERROR(INDEX(Configurações!$B$5:$B$100,MATCH($C105,Configurações!$A$5:$A$100,0)),0)) | H105: =IF(OR($A105="",'Importar Reservas'!M97<>"Aprovado",$D105<=0),"",MAX(0,IF($F105="Margem",$D105-$E105,$D105))*$G105)
A106: =IF('Importar Reservas'!A98="","",'Importar Reservas'!A98) | B106: =IF($A106="","",'Importar Reservas'!B98) | C106: =IF($A106="","",'Importar Reservas'!Z98) | D106: =IF($A106="","",IF('Importar Reservas'!O98="",0,'Importar Reservas'!O98)) | E106: =IF($A106="","",IF('Importar Reservas'!N98="",0,'Importar Reservas'!N98)) | F106: =IF($A106="","",IFERROR(INDEX(Configurações!$C$5:$C$100,MATCH($C106,Configurações!$A$5:$A$100,0)),"Margem")) | G106: =IF($A106="","",IFERROR(INDEX(Configurações!$B$5:$B$100,MATCH($C106,Configurações!$A$5:$A$100,0)),0)) | H106: =IF(OR($A106="",'Importar Reservas'!M98<>"Aprovado",$D106<=0),"",MAX(0,IF($F106="Margem",$D106-$E106,$D106))*$G106)
A107: =IF('Importar Reservas'!A99="","",'Importar Reservas'!A99) | B107: =IF($A107="","",'Importar Reservas'!B99) | C107: =IF($A107="","",'Importar Reservas'!Z99) | D107: =IF($A107="","",IF('Importar Reservas'!O99="",0,'Importar Reservas'!O99)) | E107: =IF($A107="","",IF('Importar Reservas'!N99="",0,'Importar Reservas'!N99)) | F107: =IF($A107="","",IFERROR(INDEX(Configurações!$C$5:$C$100,MATCH($C107,Configurações!$A$5:$A$100,0)),"Margem")) | G107: =IF($A107="","",IFERROR(INDEX(Configurações!$B$5:$B$100,MATCH($C107,Configurações!$A$5:$A$100,0)),0)) | H107: =IF(OR($A107="",'Importar Reservas'!M99<>"Aprovado",$D107<=0),"",MAX(0,IF($F107="Margem",$D107-$E107,$D107))*$G107)
A108: =IF('Importar Reservas'!A100="","",'Importar Reservas'!A100) | B108: =IF($A108="","",'Importar Reservas'!B100) | C108: =IF($A108="","",'Importar Reservas'!Z100) | D108: =IF($A108="","",IF('Importar Reservas'!O100="",0,'Importar Reservas'!O100)) | E108: =IF($A108="","",IF('Importar Reservas'!N100="",0,'Importar Reservas'!N100)) | F108: =IF($A108="","",IFERROR(INDEX(Configurações!$C$5:$C$100,MATCH($C108,Configurações!$A$5:$A$100,0)),"Margem")) | G108: =IF($A108="","",IFERROR(INDEX(Configurações!$B$5:$B$100,MATCH($C108,Configurações!$A$5:$A$100,0)),0)) | H108: =IF(OR($A108="",'Importar Reservas'!M100<>"Aprovado",$D108<=0),"",MAX(0,IF($F108="Margem",$D108-$E108,$D108))*$G108)
A109: =IF('Importar Reservas'!A101="","",'Importar Reservas'!A101) | B109: =IF($A109="","",'Importar Reservas'!B101) | C109: =IF($A109="","",'Importar Reservas'!Z101) | D109: =IF($A109="","",IF('Importar Reservas'!O101="",0,'Importar Reservas'!O101)) | E109: =IF($A109="","",IF('Importar Reservas'!N101="",0,'Importar Reservas'!N101)) | F109: =IF($A109="","",IFERROR(INDEX(Configurações!$C$5:$C$100,MATCH($C109,Configurações!$A$5:$A$100,0)),"Margem")) | G109: =IF($A109="","",IFERROR(INDEX(Configurações!$B$5:$B$100,MATCH($C109,Configurações!$A$5:$A$100,0)),0)) | H109: =IF(OR($A109="",'Importar Reservas'!M101<>"Aprovado",$D109<=0),"",MAX(0,IF($F109="Margem",$D109-$E109,$D109))*$G109)
A110: =IF('Importar Reservas'!A102="","",'Importar Reservas'!A102) | B110: =IF($A110="","",'Importar Reservas'!B102) | C110: =IF($A110="","",'Importar Reservas'!Z102) | D110: =IF($A110="","",IF('Importar Reservas'!O102="",0,'Importar Reservas'!O102)) | E110: =IF($A110="","",IF('Importar Reservas'!N102="",0,'Importar Reservas'!N102)) | F110: =IF($A110="","",IFERROR(INDEX(Configurações!$C$5:$C$100,MATCH($C110,Configurações!$A$5:$A$100,0)),"Margem")) | G110: =IF($A110="","",IFERROR(INDEX(Configurações!$B$5:$B$100,MATCH($C110,Configurações!$A$5:$A$100,0)),0)) | H110: =IF(OR($A110="",'Importar Reservas'!M102<>"Aprovado",$D110<=0),"",MAX(0,IF($F110="Margem",$D110-$E110,$D110))*$G110)
A111: =IF('Importar Reservas'!A103="","",'Importar Reservas'!A103) | B111: =IF($A111="","",'Importar Reservas'!B103) | C111: =IF($A111="","",'Importar Reservas'!Z103) | D111: =IF($A111="","",IF('Importar Reservas'!O103="",0,'Importar Reservas'!O103)) | E111: =IF($A111="","",IF('Importar Reservas'!N103="",0,'Importar Reservas'!N103)) | F111: =IF($A111="","",IFERROR(INDEX(Configurações!$C$5:$C$100,MATCH($C111,Configurações!$A$5:$A$100,0)),"Margem")) | G111: =IF($A111="","",IFERROR(INDEX(Configurações!$B$5:$B$100,MATCH($C111,Configurações!$A$5:$A$100,0)),0)) | H111: =IF(OR($A111="",'Importar Reservas'!M103<>"Aprovado",$D111<=0),"",MAX(0,IF($F111="Margem",$D111-$E111,$D111))*$G111)
A112: =IF('Importar Reservas'!A104="","",'Importar Reservas'!A104) | B112: =IF($A112="","",'Importar Reservas'!B104) | C112: =IF($A112="","",'Importar Reservas'!Z104) | D112: =IF($A112="","",IF('Importar Reservas'!O104="",0,'Importar Reservas'!O104)) | E112: =IF($A112="","",IF('Importar Reservas'!N104="",0,'Importar Reservas'!N104)) | F112: =IF($A112="","",IFERROR(INDEX(Configurações!$C$5:$C$100,MATCH($C112,Configurações!$A$5:$A$100,0)),"Margem")) | G112: =IF($A112="","",IFERROR(INDEX(Configurações!$B$5:$B$100,MATCH($C112,Configurações!$A$5:$A$100,0)),0)) | H112: =IF(OR($A112="",'Importar Reservas'!M104<>"Aprovado",$D112<=0),"",MAX(0,IF($F112="Margem",$D112-$E112,$D112))*$G112)
... A1009: =IF('Importar Reservas'!A1001="","",'Importar Reservas'!A1001) | B1009: =IF($A1009="","",'Importar Reservas'!B1001) | C1009: =IF($A1009="","",'Importar Reservas'!Z1001) | D1009: =IF($A1009="","",IF('Importar Reservas'!O1001="",0,'Importar Reservas'!O1001)) | E1009: =IF($A1009="","",IF('Importar Reservas'!N1001="",0,'Importar Reservas'!N1001)) | F1009: =IF($A1009="","",IFERROR(INDEX(Configurações!$C$5:$C$100,MATCH($C1009,Configurações!$A$5:$A$100,0)),"Margem")) | G1009: =IF($A1009="","",IFERROR(INDEX(Configurações!$B$5:$B$100,MATCH($C1009,Configurações!$A$5:$A$100,0)),0)) | H1009: =IF(OR($A1009="",'Importar Reservas'!M1001<>"Aprovado",$D1009<=0),"",MAX(0,IF($F1009="Margem",$D1009-$E1009,$D1009))*$G1009)

Sheet Custos Fixos
A1: 🏢 Custos fixos
A2: Descrição | B2: Categoria | C2: Valor (€) | D2: Periodicidade | E2: Início | F2: Fim | G2: Valor mensal equiv. (€)
A3: Renda do escritório | B3: Instalações | C3: 650 | D3: Mensal | E3: 46023 | G3: =IF($D3="Mensal",$C3,IF($D3="Trimestral",$C3/3,IF($D3="Anual",$C3/12,$C3)))
A4: Salário — Sofia | B4: Salários | C4: 900 | D4: Mensal | E4: 46023 | G4: =IF($D4="Mensal",$C4,IF($D4="Trimestral",$C4/3,IF($D4="Anual",$C4/12,$C4)))
A5: Salário — Miguel | B5: Salários | C5: 850 | D5: Mensal | E5: 46023 | G5: =IF($D5="Mensal",$C5,IF($D5="Trimestral",$C5/3,IF($D5="Anual",$C5/12,$C5)))
A6: Software de gestão | B6: Software | C6: 30 | D6: Mensal | E6: 46023 | G6: =IF($D6="Mensal",$C6,IF($D6="Trimestral",$C6/3,IF($D6="Anual",$C6/12,$C6)))
A7: Google Workspace | B7: Software | C7: 12 | D7: Mensal | E7: 46023 | G7: =IF($D7="Mensal",$C7,IF($D7="Trimestral",$C7/3,IF($D7="Anual",$C7/12,$C7)))
A8: Contabilidade | B8: Serviços | C8: 120 | D8: Mensal | E8: 46023 | G8: =IF($D8="Mensal",$C8,IF($D8="Trimestral",$C8/3,IF($D8="Anual",$C8/12,$C8)))
A9: Seguro anual | B9: Serviços | C9: 360 | D9: Anual | E9: 46023 | G9: =IF($D9="Mensal",$C9,IF($D9="Trimestral",$C9/3,IF($D9="Anual",$C9/12,$C9)))
F10: TOTAL MENSAL | G10: =SUM($G$3:$G$9)

Sheet Gastos Adicionais
A1: 🧾 Gastos adicionais
A2: Despesas fora dos custos fixos e dos fornecedores. Escreve aqui — vão sozinhas para o Fluxo de Caixa e para o P&L (Lucro).
A3: Data | B3: Categoria | C3: Descrição | D3: Valor (€) | E3: Método | F3: Observações | H3: Por categoria
A4: 46063 | B4: Marketing | C4: Anúncios Facebook/Instagram | D4: 150 | E4: MB Way | H4: Marketing | I4: =SUMIF($B$4:$B$1000,$H4,$D$4:$D$1000)
A5: 46078 | B5: Material escritório | C5: Toner + papel | D5: 60 | E5: Cartão | H5: Material escritório | I5: =SUMIF($B$4:$B$1000,$H5,$D$4:$D$1000)
A6: 46089 | B6: Deslocações | C6: Feira de turismo (combustível/portagens) | D6: 85 | E6: Numerário | H6: Equipamento | I6: =SUMIF($B$4:$B$1000,$H6,$D$4:$D$1000)
A7: 46101 | B7: Taxas/bancos | C7: Comissões bancárias | D7: 25 | E7: Débito direto | H7: Deslocações | I7: =SUMIF($B$4:$B$1000,$H7,$D$4:$D$1000)
A8: 46117 | B8: Equipamento | C8: Impressora nova | D8: 180 | E8: Transferência | H8: Taxas/bancos | I8: =SUMIF($B$4:$B$1000,$H8,$D$4:$D$1000)
H9: Formação | I9: =SUMIF($B$4:$B$1000,$H9,$D$4:$D$1000)
H10: Comunicações | I10: =SUMIF($B$4:$B$1000,$H10,$D$4:$D$1000)
H11: Manutenção | I11: =SUMIF($B$4:$B$1000,$H11,$D$4:$D$1000)
H12: Outros | I12: =SUMIF($B$4:$B$1000,$H12,$D$4:$D$1000)
H13: TOTAL | I13: =SUM($D$4:$D$1000)

Sheet Fluxo de Caixa
A1: 🔁 Fluxo de caixa
A2: Data | B2: Descrição | C2: Categoria | D2: Entrada (€) | E2: Saída (€) | F2: Saldo acumulado (€)
A3: 46054 | B3: Saldo inicial | C3: Abertura | D3: 2000 | E3: 0 | F3: =$D3-$E3
A4: 46065 | B4: Sinal R-2026-001 (João Silva) | C4: Recebimento cliente | D4: 430 | E4: 0 | F4: =$F3+$D4-$E4
A5: 46073 | B5: Pagamento R-2026-002 (Maria Santos) | C5: Recebimento cliente | D5: 8400 | E5: 0 | F5: =$F4+$D5-$E5
A6: 46075 | B6: Voos+hotel Maldivas | C6: Pagamento fornecedor | D6: 0 | E6: 6900 | F6: =$F5+$D6-$E6
A7: 46081 | B7: Custos fixos de fevereiro | C7: Custo fixo | D7: 0 | E7: 2592 | F7: =$F6+$D7-$E7
A8: 46086 | B8: Pagamento R-2026-003 (Pedro Costa) | C8: Recebimento cliente | D8: 1250 | E8: 0 | F8: =$F7+$D8-$E8
A9: 46087 | B9: Voos+hotel Roma | C9: Pagamento fornecedor | D9: 0 | E9: 890 | F9: =$F8+$D9-$E9
A10: 46096 | B10: Pagamento R-2026-004 (Ana Ferreira) | C10: Recebimento cliente | D10: 145 | E10: 0 | F10: =$F9+$D10-$E10
A11: 46103 | B11: Prestações Safari R-2026-005 | C11: Recebimento cliente | D11: 5200 | E11: 0 | F11: =$F10+$D11-$E11
A12: 46109 | B12: Comissões de fevereiro | C12: Comissão | D12: 0 | E12: 102 | F12: =$F11+$D12-$E12
A13: 46112 | B13: Custos fixos de março | C13: Custo fixo | D13: 0 | E13: 2592 | F13: =$F12+$D13-$E13
B15: — Gastos adicionais (automático) —
A16: =IF('Gastos Adicionais'!$A4="","",'Gastos Adicionais'!$A4) | B16: =IF('Gastos Adicionais'!$A4="","","Gasto: "&'Gastos Adicionais'!$C4) | C16: =IF('Gastos Adicionais'!$A4="","",'Gastos Adicionais'!$B4) | E16: =IF('Gastos Adicionais'!$A4="","",'Gastos Adicionais'!$D4) | F16: =IF('Gastos Adicionais'!$A4="","",$F$13-SUM('Gastos Adicionais'!$D$4:$D4))
A17: =IF('Gastos Adicionais'!$A5="","",'Gastos Adicionais'!$A5) | B17: =IF('Gastos Adicionais'!$A5="","","Gasto: "&'Gastos Adicionais'!$C5) | C17: =IF('Gastos Adicionais'!$A5="","",'Gastos Adicionais'!$B5) | E17: =IF('Gastos Adicionais'!$A5="","",'Gastos Adicionais'!$D5) | F17: =IF('Gastos Adicionais'!$A5="","",$F$13-SUM('Gastos Adicionais'!$D$4:$D5))
A18: =IF('Gastos Adicionais'!$A6="","",'Gastos Adicionais'!$A6) | B18: =IF('Gastos Adicionais'!$A6="","","Gasto: "&'Gastos Adicionais'!$C6) | C18: =IF('Gastos Adicionais'!$A6="","",'Gastos Adicionais'!$B6) | E18: =IF('Gastos Adicionais'!$A6="","",'Gastos Adicionais'!$D6) | F18: =IF('Gastos Adicionais'!$A6="","",$F$13-SUM('Gastos Adicionais'!$D$4:$D6))
A19: =IF('Gastos Adicionais'!$A7="","",'Gastos Adicionais'!$A7) | B19: =IF('Gastos Adicionais'!$A7="","","Gasto: "&'Gastos Adicionais'!$C7) | C19: =IF('Gastos Adicionais'!$A7="","",'Gastos Adicionais'!$B7) | E19: =IF('Gastos Adicionais'!$A7="","",'Gastos Adicionais'!$D7) | F19: =IF('Gastos Adicionais'!$A7="","",$F$13-SUM('Gastos Adicionais'!$D$4:$D7))
A20: =IF('Gastos Adicionais'!$A8="","",'Gastos Adicionais'!$A8) | B20: =IF('Gastos Adicionais'!$A8="","","Gasto: "&'Gastos Adicionais'!$C8) | C20: =IF('Gastos Adicionais'!$A8="","",'Gastos Adicionais'!$B8) | E20: =IF('Gastos Adicionais'!$A8="","",'Gastos Adicionais'!$D8) | F20: =IF('Gastos Adicionais'!$A8="","",$F$13-SUM('Gastos Adicionais'!$D$4:$D8))
A21: =IF('Gastos Adicionais'!$A9="","",'Gastos Adicionais'!$A9) | B21: =IF('Gastos Adicionais'!$A9="","","Gasto: "&'Gastos Adicionais'!$C9) | C21: =IF('Gastos Adicionais'!$A9="","",'Gastos Adicionais'!$B9) | E21: =IF('Gastos Adicionais'!$A9="","",'Gastos Adicionais'!$D9) | F21: =IF('Gastos Adicionais'!$A9="","",$F$13-SUM('Gastos Adicionais'!$D$4:$D9))
A22: =IF('Gastos Adicionais'!$A10="","",'Gastos Adicionais'!$A10) | B22: =IF('Gastos Adicionais'!$A10="","","Gasto: "&'Gastos Adicionais'!$C10) | C22: =IF('Gastos Adicionais'!$A10="","",'Gastos Adicionais'!$B10) | E22: =IF('Gastos Adicionais'!$A10="","",'Gastos Adicionais'!$D10) | F22: =IF('Gastos Adicionais'!$A10="","",$F$13-SUM('Gastos Adicionais'!$D$4:$D10))
A23: =IF('Gastos Adicionais'!$A11="","",'Gastos Adicionais'!$A11) | B23: =IF('Gastos Adicionais'!$A11="","","Gasto: "&'Gastos Adicionais'!$C11) | C23: =IF('Gastos Adicionais'!$A11="","",'Gastos Adicionais'!$B11) | E23: =IF('Gastos Adicionais'!$A11="","",'Gastos Adicionais'!$D11) | F23: =IF('Gastos Adicionais'!$A11="","",$F$13-SUM('Gastos Adicionais'!$D$4:$D11))
A24: =IF('Gastos Adicionais'!$A12="","",'Gastos Adicionais'!$A12) | B24: =IF('Gastos Adicionais'!$A12="","","Gasto: "&'Gastos Adicionais'!$C12) | C24: =IF('Gastos Adicionais'!$A12="","",'Gastos Adicionais'!$B12) | E24: =IF('Gastos Adicionais'!$A12="","",'Gastos Adicionais'!$D12) | F24: =IF('Gastos Adicionais'!$A12="","",$F$13-SUM('Gastos Adicionais'!$D$4:$D12))
A25: =IF('Gastos Adicionais'!$A13="","",'Gastos Adicionais'!$A13) | B25: =IF('Gastos Adicionais'!$A13="","","Gasto: "&'Gastos Adicionais'!$C13) | C25: =IF('Gastos Adicionais'!$A13="","",'Gastos Adicionais'!$B13) | E25: =IF('Gastos Adicionais'!$A13="","",'Gastos Adicionais'!$D13) | F25: =IF('Gastos Adicionais'!$A13="","",$F$13-SUM('Gastos Adicionais'!$D$4:$D13))
A26: =IF('Gastos Adicionais'!$A14="","",'Gastos Adicionais'!$A14) | B26: =IF('Gastos Adicionais'!$A14="","","Gasto: "&'Gastos Adicionais'!$C14) | C26: =IF('Gastos Adicionais'!$A14="","",'Gastos Adicionais'!$B14) | E26: =IF('Gastos Adicionais'!$A14="","",'Gastos Adicionais'!$D14) | F26: =IF('Gastos Adicionais'!$A14="","",$F$13-SUM('Gastos Adicionais'!$D$4:$D14))
A27: =IF('Gastos Adicionais'!$A15="","",'Gastos Adicionais'!$A15) | B27: =IF('Gastos Adicionais'!$A15="","","Gasto: "&'Gastos Adicionais'!$C15) | C27: =IF('Gastos Adicionais'!$A15="","",'Gastos Adicionais'!$B15) | E27: =IF('Gastos Adicionais'!$A15="","",'Gastos Adicionais'!$D15) | F27: =IF('Gastos Adicionais'!$A15="","",$F$13-SUM('Gastos Adicionais'!$D$4:$D15))
... A45: =IF('Gastos Adicionais'!$A33="","",'Gastos Adicionais'!$A33) | B45: =IF('Gastos Adicionais'!$A33="","","Gasto: "&'Gastos Adicionais'!$C33) | C45: =IF('Gastos Adicionais'!$A33="","",'Gastos Adicionais'!$B33) | E45: =IF('Gastos Adicionais'!$A33="","",'Gastos Adicionais'!$D33) | F45: =IF('Gastos Adicionais'!$A33="","",$F$13-SUM('Gastos Adicionais'!$D$4:$D33))
E47: Saldo de caixa (final): | F47: =$F$13-SUM('Gastos Adicionais'!$D$4:$D$1000)

Sheet Contas a Receber
A1: ⏳ Contas a receber
A2: Quanto falta receber de cada cliente
A3: ID Reserva | B3: Cliente | C3: Viagem | D3: Total (€) | E3: Recebido (€) | F3: Em falta (€) | G3: Prestações | H3: Faltam | I3: Próx. prestação (€) | J3: % recebido | K3: Progresso
A4: =IF('Importar Reservas'!$A3="","",'Importar Reservas'!$A3) | B4: =IF('Importar Reservas'!$A3="","",'Importar Reservas'!$D3) | C4: =IF('Importar Reservas'!$A3="","",'Importar Reservas'!$F3) | D4: =IF('Importar Reservas'!$A3="","",'Importar Reservas'!$O3) | E4: =IF('Importar Reservas'!$A3="","",'Importar Reservas'!$V3) | F4: =IF('Importar Reservas'!$A3="","",'Importar Reservas'!$W3) | G4: =IF('Importar Reservas'!$A3="","",'Importar Reservas'!$T3&" / "&'Importar Reservas'!$S3) | H4: =IF('Importar Reservas'!$A3="","",'Importar Reservas'!$X3) | I4: =IF('Importar Reservas'!$A3="","",IF('Importar Reservas'!$X3>0,'Importar Reservas'!$U3,0)) | J4: =IF('Importar Reservas'!$A3="","",'Importar Reservas'!$Y3) | K4: =IF('Importar Reservas'!$A3="","",REPT("█",ROUND(IF('Importar Reservas'!$Y3="",0,'Importar Reservas'!$Y3)*10,0))&REPT("░",10-ROUND(IF('Importar Reservas'!$Y3="",0,'Importar Reservas'!$Y3)*10,0)))
A5: =IF('Importar Reservas'!$A4="","",'Importar Reservas'!$A4) | B5: =IF('Importar Reservas'!$A4="","",'Importar Reservas'!$D4) | C5: =IF('Importar Reservas'!$A4="","",'Importar Reservas'!$F4) | D5: =IF('Importar Reservas'!$A4="","",'Importar Reservas'!$O4) | E5: =IF('Importar Reservas'!$A4="","",'Importar Reservas'!$V4) | F5: =IF('Importar Reservas'!$A4="","",'Importar Reservas'!$W4) | G5: =IF('Importar Reservas'!$A4="","",'Importar Reservas'!$T4&" / "&'Importar Reservas'!$S4) | H5: =IF('Importar Reservas'!$A4="","",'Importar Reservas'!$X4) | I5: =IF('Importar Reservas'!$A4="","",IF('Importar Reservas'!$X4>0,'Importar Reservas'!$U4,0)) | J5: =IF('Importar Reservas'!$A4="","",'Importar Reservas'!$Y4) | K5: =IF('Importar Reservas'!$A4="","",REPT("█",ROUND(IF('Importar Reservas'!$Y4="",0,'Importar Reservas'!$Y4)*10,0))&REPT("░",10-ROUND(IF('Importar Reservas'!$Y4="",0,'Importar Reservas'!$Y4)*10,0)))
A6: =IF('Importar Reservas'!$A5="","",'Importar Reservas'!$A5) | B6: =IF('Importar Reservas'!$A5="","",'Importar Reservas'!$D5) | C6: =IF('Importar Reservas'!$A5="","",'Importar Reservas'!$F5) | D6: =IF('Importar Reservas'!$A5="","",'Importar Reservas'!$O5) | E6: =IF('Importar Reservas'!$A5="","",'Importar Reservas'!$V5) | F6: =IF('Importar Reservas'!$A5="","",'Importar Reservas'!$W5) | G6: =IF('Importar Reservas'!$A5="","",'Importar Reservas'!$T5&" / "&'Importar Reservas'!$S5) | H6: =IF('Importar Reservas'!$A5="","",'Importar Reservas'!$X5) | I6: =IF('Importar Reservas'!$A5="","",IF('Importar Reservas'!$X5>0,'Importar Reservas'!$U5,0)) | J6: =IF('Importar Reservas'!$A5="","",'Importar Reservas'!$Y5) | K6: =IF('Importar Reservas'!$A5="","",REPT("█",ROUND(IF('Importar Reservas'!$Y5="",0,'Importar Reservas'!$Y5)*10,0))&REPT("░",10-ROUND(IF('Importar Reservas'!$Y5="",0,'Importar Reservas'!$Y5)*10,0)))
A7: =IF('Importar Reservas'!$A6="","",'Importar Reservas'!$A6) | B7: =IF('Importar Reservas'!$A6="","",'Importar Reservas'!$D6) | C7: =IF('Importar Reservas'!$A6="","",'Importar Reservas'!$F6) | D7: =IF('Importar Reservas'!$A6="","",'Importar Reservas'!$O6) | E7: =IF('Importar Reservas'!$A6="","",'Importar Reservas'!$V6) | F7: =IF('Importar Reservas'!$A6="","",'Importar Reservas'!$W6) | G7: =IF('Importar Reservas'!$A6="","",'Importar Reservas'!$T6&" / "&'Importar Reservas'!$S6) | H7: =IF('Importar Reservas'!$A6="","",'Importar Reservas'!$X6) | I7: =IF('Importar Reservas'!$A6="","",IF('Importar Reservas'!$X6>0,'Importar Reservas'!$U6,0)) | J7: =IF('Importar Reservas'!$A6="","",'Importar Reservas'!$Y6) | K7: =IF('Importar Reservas'!$A6="","",REPT("█",ROUND(IF('Importar Reservas'!$Y6="",0,'Importar Reservas'!$Y6)*10,0))&REPT("░",10-ROUND(IF('Importar Reservas'!$Y6="",0,'Importar Reservas'!$Y6)*10,0)))
A8: =IF('Importar Reservas'!$A7="","",'Importar Reservas'!$A7) | B8: =IF('Importar Reservas'!$A7="","",'Importar Reservas'!$D7) | C8: =IF('Importar Reservas'!$A7="","",'Importar Reservas'!$F7) | D8: =IF('Importar Reservas'!$A7="","",'Importar Reservas'!$O7) | E8: =IF('Importar Reservas'!$A7="","",'Importar Reservas'!$V7) | F8: =IF('Importar Reservas'!$A7="","",'Importar Reservas'!$W7) | G8: =IF('Importar Reservas'!$A7="","",'Importar Reservas'!$T7&" / "&'Importar Reservas'!$S7) | H8: =IF('Importar Reservas'!$A7="","",'Importar Reservas'!$X7) | I8: =IF('Importar Reservas'!$A7="","",IF('Importar Reservas'!$X7>0,'Importar Reservas'!$U7,0)) | J8: =IF('Importar Reservas'!$A7="","",'Importar Reservas'!$Y7) | K8: =IF('Importar Reservas'!$A7="","",REPT("█",ROUND(IF('Importar Reservas'!$Y7="",0,'Importar Reservas'!$Y7)*10,0))&REPT("░",10-ROUND(IF('Importar Reservas'!$Y7="",0,'Importar Reservas'!$Y7)*10,0)))
A9: =IF('Importar Reservas'!$A8="","",'Importar Reservas'!$A8) | B9: =IF('Importar Reservas'!$A8="","",'Importar Reservas'!$D8) | C9: =IF('Importar Reservas'!$A8="","",'Importar Reservas'!$F8) | D9: =IF('Importar Reservas'!$A8="","",'Importar Reservas'!$O8) | E9: =IF('Importar Reservas'!$A8="","",'Importar Reservas'!$V8) | F9: =IF('Importar Reservas'!$A8="","",'Importar Reservas'!$W8) | G9: =IF('Importar Reservas'!$A8="","",'Importar Reservas'!$T8&" / "&'Importar Reservas'!$S8) | H9: =IF('Importar Reservas'!$A8="","",'Importar Reservas'!$X8) | I9: =IF('Importar Reservas'!$A8="","",IF('Importar Reservas'!$X8>0,'Importar Reservas'!$U8,0)) | J9: =IF('Importar Reservas'!$A8="","",'Importar Reservas'!$Y8) | K9: =IF('Importar Reservas'!$A8="","",REPT("█",ROUND(IF('Importar Reservas'!$Y8="",0,'Importar Reservas'!$Y8)*10,0))&REPT("░",10-ROUND(IF('Importar Reservas'!$Y8="",0,'Importar Reservas'!$Y8)*10,0)))
A10: =IF('Importar Reservas'!$A9="","",'Importar Reservas'!$A9) | B10: =IF('Importar Reservas'!$A9="","",'Importar Reservas'!$D9) | C10: =IF('Importar Reservas'!$A9="","",'Importar Reservas'!$F9) | D10: =IF('Importar Reservas'!$A9="","",'Importar Reservas'!$O9) | E10: =IF('Importar Reservas'!$A9="","",'Importar Reservas'!$V9) | F10: =IF('Importar Reservas'!$A9="","",'Importar Reservas'!$W9) | G10: =IF('Importar Reservas'!$A9="","",'Importar Reservas'!$T9&" / "&'Importar Reservas'!$S9) | H10: =IF('Importar Reservas'!$A9="","",'Importar Reservas'!$X9) | I10: =IF('Importar Reservas'!$A9="","",IF('Importar Reservas'!$X9>0,'Importar Reservas'!$U9,0)) | J10: =IF('Importar Reservas'!$A9="","",'Importar Reservas'!$Y9) | K10: =IF('Importar Reservas'!$A9="","",REPT("█",ROUND(IF('Importar Reservas'!$Y9="",0,'Importar Reservas'!$Y9)*10,0))&REPT("░",10-ROUND(IF('Importar Reservas'!$Y9="",0,'Importar Reservas'!$Y9)*10,0)))
A11: =IF('Importar Reservas'!$A10="","",'Importar Reservas'!$A10) | B11: =IF('Importar Reservas'!$A10="","",'Importar Reservas'!$D10) | C11: =IF('Importar Reservas'!$A10="","",'Importar Reservas'!$F10) | D11: =IF('Importar Reservas'!$A10="","",'Importar Reservas'!$O10) | E11: =IF('Importar Reservas'!$A10="","",'Importar Reservas'!$V10) | F11: =IF('Importar Reservas'!$A10="","",'Importar Reservas'!$W10) | G11: =IF('Importar Reservas'!$A10="","",'Importar Reservas'!$T10&" / "&'Importar Reservas'!$S10) | H11: =IF('Importar Reservas'!$A10="","",'Importar Reservas'!$X10) | I11: =IF('Importar Reservas'!$A10="","",IF('Importar Reservas'!$X10>0,'Importar Reservas'!$U10,0)) | J11: =IF('Importar Reservas'!$A10="","",'Importar Reservas'!$Y10) | K11: =IF('Importar Reservas'!$A10="","",REPT("█",ROUND(IF('Importar Reservas'!$Y10="",0,'Importar Reservas'!$Y10)*10,0))&REPT("░",10-ROUND(IF('Importar Reservas'!$Y10="",0,'Importar Reservas'!$Y10)*10,0)))
A12: =IF('Importar Reservas'!$A11="","",'Importar Reservas'!$A11) | B12: =IF('Importar Reservas'!$A11="","",'Importar Reservas'!$D11) | C12: =IF('Importar Reservas'!$A11="","",'Importar Reservas'!$F11) | D12: =IF('Importar Reservas'!$A11="","",'Importar Reservas'!$O11) | E12: =IF('Importar Reservas'!$A11="","",'Importar Reservas'!$V11) | F12: =IF('Importar Reservas'!$A11="","",'Importar Reservas'!$W11) | G12: =IF('Importar Reservas'!$A11="","",'Importar Reservas'!$T11&" / "&'Importar Reservas'!$S11) | H12: =IF('Importar Reservas'!$A11="","",'Importar Reservas'!$X11) | I12: =IF('Importar Reservas'!$A11="","",IF('Importar Reservas'!$X11>0,'Importar Reservas'!$U11,0)) | J12: =IF('Importar Reservas'!$A11="","",'Importar Reservas'!$Y11) | K12: =IF('Importar Reservas'!$A11="","",REPT("█",ROUND(IF('Importar Reservas'!$Y11="",0,'Importar Reservas'!$Y11)*10,0))&REPT("░",10-ROUND(IF('Importar Reservas'!$Y11="",0,'Importar Reservas'!$Y11)*10,0)))
A13: =IF('Importar Reservas'!$A12="","",'Importar Reservas'!$A12) | B13: =IF('Importar Reservas'!$A12="","",'Importar Reservas'!$D12) | C13: =IF('Importar Reservas'!$A12="","",'Importar Reservas'!$F12) | D13: =IF('Importar Reservas'!$A12="","",'Importar Reservas'!$O12) | E13: =IF('Importar Reservas'!$A12="","",'Importar Reservas'!$V12) | F13: =IF('Importar Reservas'!$A12="","",'Importar Reservas'!$W12) | G13: =IF('Importar Reservas'!$A12="","",'Importar Reservas'!$T12&" / "&'Importar Reservas'!$S12) | H13: =IF('Importar Reservas'!$A12="","",'Importar Reservas'!$X12) | I13: =IF('Importar Reservas'!$A12="","",IF('Importar Reservas'!$X12>0,'Importar Reservas'!$U12,0)) | J13: =IF('Importar Reservas'!$A12="","",'Importar Reservas'!$Y12) | K13: =IF('Importar Reservas'!$A12="","",REPT("█",ROUND(IF('Importar Reservas'!$Y12="",0,'Importar Reservas'!$Y12)*10,0))&REPT("░",10-ROUND(IF('Importar Reservas'!$Y12="",0,'Importar Reservas'!$Y12)*10,0)))
A14: =IF('Importar Reservas'!$A13="","",'Importar Reservas'!$A13) | B14: =IF('Importar Reservas'!$A13="","",'Importar Reservas'!$D13) | C14: =IF('Importar Reservas'!$A13="","",'Importar Reservas'!$F13) | D14: =IF('Importar Reservas'!$A13="","",'Importar Reservas'!$O13) | E14: =IF('Importar Reservas'!$A13="","",'Importar Reservas'!$V13) | F14: =IF('Importar Reservas'!$A13="","",'Importar Reservas'!$W13) | G14: =IF('Importar Reservas'!$A13="","",'Importar Reservas'!$T13&" / "&'Importar Reservas'!$S13) | H14: =IF('Importar Reservas'!$A13="","",'Importar Reservas'!$X13) | I14: =IF('Importar Reservas'!$A13="","",IF('Importar Reservas'!$X13>0,'Importar Reservas'!$U13,0)) | J14: =IF('Importar Reservas'!$A13="","",'Importar Reservas'!$Y13) | K14: =IF('Importar Reservas'!$A13="","",REPT("█",ROUND(IF('Importar Reservas'!$Y13="",0,'Importar Reservas'!$Y13)*10,0))&REPT("░",10-ROUND(IF('Importar Reservas'!$Y13="",0,'Importar Reservas'!$Y13)*10,0)))
A15: =IF('Importar Reservas'!$A14="","",'Importar Reservas'!$A14) | B15: =IF('Importar Reservas'!$A14="","",'Importar Reservas'!$D14) | C15: =IF('Importar Reservas'!$A14="","",'Importar Reservas'!$F14) | D15: =IF('Importar Reservas'!$A14="","",'Importar Reservas'!$O14) | E15: =IF('Importar Reservas'!$A14="","",'Importar Reservas'!$V14) | F15: =IF('Importar Reservas'!$A14="","",'Importar Reservas'!$W14) | G15: =IF('Importar Reservas'!$A14="","",'Importar Reservas'!$T14&" / "&'Importar Reservas'!$S14) | H15: =IF('Importar Reservas'!$A14="","",'Importar Reservas'!$X14) | I15: =IF('Importar Reservas'!$A14="","",IF('Importar Reservas'!$X14>0,'Importar Reservas'!$U14,0)) | J15: =IF('Importar Reservas'!$A14="","",'Importar Reservas'!$Y14) | K15: =IF('Importar Reservas'!$A14="","",REPT("█",ROUND(IF('Importar Reservas'!$Y14="",0,'Importar Reservas'!$Y14)*10,0))&REPT("░",10-ROUND(IF('Importar Reservas'!$Y14="",0,'Importar Reservas'!$Y14)*10,0)))
... A43: =IF('Importar Reservas'!$A42="","",'Importar Reservas'!$A42) | B43: =IF('Importar Reservas'!$A42="","",'Importar Reservas'!$D42) | C43: =IF('Importar Reservas'!$A42="","",'Importar Reservas'!$F42) | D43: =IF('Importar Reservas'!$A42="","",'Importar Reservas'!$O42) | E43: =IF('Importar Reservas'!$A42="","",'Importar Reservas'!$V42) | F43: =IF('Importar Reservas'!$A42="","",'Importar Reservas'!$W42) | G43: =IF('Importar Reservas'!$A42="","",'Importar Reservas'!$T42&" / "&'Importar Reservas'!$S42) | H43: =IF('Importar Reservas'!$A42="","",'Importar Reservas'!$X42) | I43: =IF('Importar Reservas'!$A42="","",IF('Importar Reservas'!$X42>0,'Importar Reservas'!$U42,0)) | J43: =IF('Importar Reservas'!$A42="","",'Importar Reservas'!$Y42) | K43: =IF('Importar Reservas'!$A42="","",REPT("█",ROUND(IF('Importar Reservas'!$Y42="",0,'Importar Reservas'!$Y42)*10,0))&REPT("░",10-ROUND(IF('Importar Reservas'!$Y42="",0,'Importar Reservas'!$Y42)*10,0)))
B46: Já recebido | C46: =SUM(E4:E43)
B47: A receber | C47: =SUM(F4:F43)

Sheet Rendimentos e Lucros
A1: 📈 Rendimentos e lucros (P&L) — ano selecionado
A2: Competência pela data de registo. O ano é definido em Configurações!B16.
A4: Rubrica | B4: jan | C4: fev | D4: mar | E4: abr | F4: mai | G4: jun | H4: jul | I4: ago | J4: set | K4: out | L4: nov | M4: dez | N4: Total
A5: Receita (venda) | B5: =SUMIFS('Importar Reservas'!$O:$O,'Importar Reservas'!$B:$B,">="&DATE(Configurações!$B$16,1,1),'Importar Reservas'!$B:$B,"<"&EDATE(DATE(Configurações!$B$16,1,1),1)) | C5: =SUMIFS('Importar Reservas'!$O:$O,'Importar Reservas'!$B:$B,">="&DATE(Configurações!$B$16,2,1),'Importar Reservas'!$B:$B,"<"&EDATE(DATE(Configurações!$B$16,2,1),1)) | D5: =SUMIFS('Importar Reservas'!$O:$O,'Importar Reservas'!$B:$B,">="&DATE(Configurações!$B$16,3,1),'Importar Reservas'!$B:$B,"<"&EDATE(DATE(Configurações!$B$16,3,1),1)) | E5: =SUMIFS('Importar Reservas'!$O:$O,'Importar Reservas'!$B:$B,">="&DATE(Configurações!$B$16,4,1),'Importar Reservas'!$B:$B,"<"&EDATE(DATE(Configurações!$B$16,4,1),1)) | F5: =SUMIFS('Importar Reservas'!$O:$O,'Importar Reservas'!$B:$B,">="&DATE(Configurações!$B$16,5,1),'Importar Reservas'!$B:$B,"<"&EDATE(DATE(Configurações!$B$16,5,1),1)) | G5: =SUMIFS('Importar Reservas'!$O:$O,'Importar Reservas'!$B:$B,">="&DATE(Configurações!$B$16,6,1),'Importar Reservas'!$B:$B,"<"&EDATE(DATE(Configurações!$B$16,6,1),1)) | H5: =SUMIFS('Importar Reservas'!$O:$O,'Importar Reservas'!$B:$B,">="&DATE(Configurações!$B$16,7,1),'Importar Reservas'!$B:$B,"<"&EDATE(DATE(Configurações!$B$16,7,1),1)) | I5: =SUMIFS('Importar Reservas'!$O:$O,'Importar Reservas'!$B:$B,">="&DATE(Configurações!$B$16,8,1),'Importar Reservas'!$B:$B,"<"&EDATE(DATE(Configurações!$B$16,8,1),1)) | J5: =SUMIFS('Importar Reservas'!$O:$O,'Importar Reservas'!$B:$B,">="&DATE(Configurações!$B$16,9,1),'Importar Reservas'!$B:$B,"<"&EDATE(DATE(Configurações!$B$16,9,1),1)) | K5: =SUMIFS('Importar Reservas'!$O:$O,'Importar Reservas'!$B:$B,">="&DATE(Configurações!$B$16,10,1),'Importar Reservas'!$B:$B,"<"&EDATE(DATE(Configurações!$B$16,10,1),1)) | L5: =SUMIFS('Importar Reservas'!$O:$O,'Importar Reservas'!$B:$B,">="&DATE(Configurações!$B$16,11,1),'Importar Reservas'!$B:$B,"<"&EDATE(DATE(Configurações!$B$16,11,1),1)) | M5: =SUMIFS('Importar Reservas'!$O:$O,'Importar Reservas'!$B:$B,">="&DATE(Configurações!$B$16,12,1),'Importar Reservas'!$B:$B,"<"&EDATE(DATE(Configurações!$B$16,12,1),1)) | N5: =SUM(B5:M5)
A6: Custo dos fornecedores | B6: =SUMIFS('Importar Reservas'!$N:$N,'Importar Reservas'!$B:$B,">="&DATE(Configurações!$B$16,1,1),'Importar Reservas'!$B:$B,"<"&EDATE(DATE(Configurações!$B$16,1,1),1),'Importar Reservas'!$O:$O,">0") | C6: =SUMIFS('Importar Reservas'!$N:$N,'Importar Reservas'!$B:$B,">="&DATE(Configurações!$B$16,2,1),'Importar Reservas'!$B:$B,"<"&EDATE(DATE(Configurações!$B$16,2,1),1),'Importar Reservas'!$O:$O,">0") | D6: =SUMIFS('Importar Reservas'!$N:$N,'Importar Reservas'!$B:$B,">="&DATE(Configurações!$B$16,3,1),'Importar Reservas'!$B:$B,"<"&EDATE(DATE(Configurações!$B$16,3,1),1),'Importar Reservas'!$O:$O,">0") | E6: =SUMIFS('Importar Reservas'!$N:$N,'Importar Reservas'!$B:$B,">="&DATE(Configurações!$B$16,4,1),'Importar Reservas'!$B:$B,"<"&EDATE(DATE(Configurações!$B$16,4,1),1),'Importar Reservas'!$O:$O,">0") | F6: =SUMIFS('Importar Reservas'!$N:$N,'Importar Reservas'!$B:$B,">="&DATE(Configurações!$B$16,5,1),'Importar Reservas'!$B:$B,"<"&EDATE(DATE(Configurações!$B$16,5,1),1),'Importar Reservas'!$O:$O,">0") | G6: =SUMIFS('Importar Reservas'!$N:$N,'Importar Reservas'!$B:$B,">="&DATE(Configurações!$B$16,6,1),'Importar Reservas'!$B:$B,"<"&EDATE(DATE(Configurações!$B$16,6,1),1),'Importar Reservas'!$O:$O,">0") | H6: =SUMIFS('Importar Reservas'!$N:$N,'Importar Reservas'!$B:$B,">="&DATE(Configurações!$B$16,7,1),'Importar Reservas'!$B:$B,"<"&EDATE(DATE(Configurações!$B$16,7,1),1),'Importar Reservas'!$O:$O,">0") | I6: =SUMIFS('Importar Reservas'!$N:$N,'Importar Reservas'!$B:$B,">="&DATE(Configurações!$B$16,8,1),'Importar Reservas'!$B:$B,"<"&EDATE(DATE(Configurações!$B$16,8,1),1),'Importar Reservas'!$O:$O,">0") | J6: =SUMIFS('Importar Reservas'!$N:$N,'Importar Reservas'!$B:$B,">="&DATE(Configurações!$B$16,9,1),'Importar Reservas'!$B:$B,"<"&EDATE(DATE(Configurações!$B$16,9,1),1),'Importar Reservas'!$O:$O,">0") | K6: =SUMIFS('Importar Reservas'!$N:$N,'Importar Reservas'!$B:$B,">="&DATE(Configurações!$B$16,10,1),'Importar Reservas'!$B:$B,"<"&EDATE(DATE(Configurações!$B$16,10,1),1),'Importar Reservas'!$O:$O,">0") | L6: =SUMIFS('Importar Reservas'!$N:$N,'Importar Reservas'!$B:$B,">="&DATE(Configurações!$B$16,11,1),'Importar Reservas'!$B:$B,"<"&EDATE(DATE(Configurações!$B$16,11,1),1),'Importar Reservas'!$O:$O,">0") | M6: =SUMIFS('Importar Reservas'!$N:$N,'Importar Reservas'!$B:$B,">="&DATE(Configurações!$B$16,12,1),'Importar Reservas'!$B:$B,"<"&EDATE(DATE(Configurações!$B$16,12,1),1),'Importar Reservas'!$O:$O,">0") | N6: =SUM(B6:M6)
A7: Margem bruta | B7: =B5-B6 | C7: =C5-C6 | D7: =D5-D6 | E7: =E5-E6 | F7: =F5-F6 | G7: =G5-G6 | H7: =H5-H6 | I7: =I5-I6 | ... M7: =M5-M6 | N7: =SUM(B7:M7)
A8: Comissões | B8: =SUMIFS(Comissões!$H:$H,Comissões!$B:$B,">="&DATE(Configurações!$B$16,1,1),Comissões!$B:$B,"<"&EDATE(DATE(Configurações!$B$16,1,1),1)) | C8: =SUMIFS(Comissões!$H:$H,Comissões!$B:$B,">="&DATE(Configurações!$B$16,2,1),Comissões!$B:$B,"<"&EDATE(DATE(Configurações!$B$16,2,1),1)) | D8: =SUMIFS(Comissões!$H:$H,Comissões!$B:$B,">="&DATE(Configurações!$B$16,3,1),Comissões!$B:$B,"<"&EDATE(DATE(Configurações!$B$16,3,1),1)) | E8: =SUMIFS(Comissões!$H:$H,Comissões!$B:$B,">="&DATE(Configurações!$B$16,4,1),Comissões!$B:$B,"<"&EDATE(DATE(Configurações!$B$16,4,1),1)) | F8: =SUMIFS(Comissões!$H:$H,Comissões!$B:$B,">="&DATE(Configurações!$B$16,5,1),Comissões!$B:$B,"<"&EDATE(DATE(Configurações!$B$16,5,1),1)) | G8: =SUMIFS(Comissões!$H:$H,Comissões!$B:$B,">="&DATE(Configurações!$B$16,6,1),Comissões!$B:$B,"<"&EDATE(DATE(Configurações!$B$16,6,1),1)) | H8: =SUMIFS(Comissões!$H:$H,Comissões!$B:$B,">="&DATE(Configurações!$B$16,7,1),Comissões!$B:$B,"<"&EDATE(DATE(Configurações!$B$16,7,1),1)) | I8: =SUMIFS(Comissões!$H:$H,Comissões!$B:$B,">="&DATE(Configurações!$B$16,8,1),Comissões!$B:$B,"<"&EDATE(DATE(Configurações!$B$16,8,1),1)) | J8: =SUMIFS(Comissões!$H:$H,Comissões!$B:$B,">="&DATE(Configurações!$B$16,9,1),Comissões!$B:$B,"<"&EDATE(DATE(Configurações!$B$16,9,1),1)) | K8: =SUMIFS(Comissões!$H:$H,Comissões!$B:$B,">="&DATE(Configurações!$B$16,10,1),Comissões!$B:$B,"<"&EDATE(DATE(Configurações!$B$16,10,1),1)) | L8: =SUMIFS(Comissões!$H:$H,Comissões!$B:$B,">="&DATE(Configurações!$B$16,11,1),Comissões!$B:$B,"<"&EDATE(DATE(Configurações!$B$16,11,1),1)) | M8: =SUMIFS(Comissões!$H:$H,Comissões!$B:$B,">="&DATE(Configurações!$B$16,12,1),Comissões!$B:$B,"<"&EDATE(DATE(Configurações!$B$16,12,1),1)) | N8: =SUM(B8:M8)
A9: Custos fixos (mensais) | B9: =SUMPRODUCT(('Custos Fixos'!$E$3:$E$100<EDATE(DATE(Configurações!$B$16,1,1),1))*(('Custos Fixos'!$F$3:$F$100="")+('Custos Fixos'!$F$3:$F$100>=DATE(Configurações!$B$16,1,1)))*'Custos Fixos'!$G$3:$G$100) | C9: =SUMPRODUCT(('Custos Fixos'!$E$3:$E$100<EDATE(DATE(Configurações!$B$16,2,1),1))*(('Custos Fixos'!$F$3:$F$100="")+('Custos Fixos'!$F$3:$F$100>=DATE(Configurações!$B$16,2,1)))*'Custos Fixos'!$G$3:$G$100) | D9: =SUMPRODUCT(('Custos Fixos'!$E$3:$E$100<EDATE(DATE(Configurações!$B$16,3,1),1))*(('Custos Fixos'!$F$3:$F$100="")+('Custos Fixos'!$F$3:$F$100>=DATE(Configurações!$B$16,3,1)))*'Custos Fixos'!$G$3:$G$100) | E9: =SUMPRODUCT(('Custos Fixos'!$E$3:$E$100<EDATE(DATE(Configurações!$B$16,4,1),1))*(('Custos Fixos'!$F$3:$F$100="")+('Custos Fixos'!$F$3:$F$100>=DATE(Configurações!$B$16,4,1)))*'Custos Fixos'!$G$3:$G$100) | F9: =SUMPRODUCT(('Custos Fixos'!$E$3:$E$100<EDATE(DATE(Configurações!$B$16,5,1),1))*(('Custos Fixos'!$F$3:$F$100="")+('Custos Fixos'!$F$3:$F$100>=DATE(Configurações!$B$16,5,1)))*'Custos Fixos'!$G$3:$G$100) | G9: =SUMPRODUCT(('Custos Fixos'!$E$3:$E$100<EDATE(DATE(Configurações!$B$16,6,1),1))*(('Custos Fixos'!$F$3:$F$100="")+('Custos Fixos'!$F$3:$F$100>=DATE(Configurações!$B$16,6,1)))*'Custos Fixos'!$G$3:$G$100) | H9: =SUMPRODUCT(('Custos Fixos'!$E$3:$E$100<EDATE(DATE(Configurações!$B$16,7,1),1))*(('Custos Fixos'!$F$3:$F$100="")+('Custos Fixos'!$F$3:$F$100>=DATE(Configurações!$B$16,7,1)))*'Custos Fixos'!$G$3:$G$100) | I9: =SUMPRODUCT(('Custos Fixos'!$E$3:$E$100<EDATE(DATE(Configurações!$B$16,8,1),1))*(('Custos Fixos'!$F$3:$F$100="")+('Custos Fixos'!$F$3:$F$100>=DATE(Configurações!$B$16,8,1)))*'Custos Fixos'!$G$3:$G$100) | J9: =SUMPRODUCT(('Custos Fixos'!$E$3:$E$100<EDATE(DATE(Configurações!$B$16,9,1),1))*(('Custos Fixos'!$F$3:$F$100="")+('Custos Fixos'!$F$3:$F$100>=DATE(Configurações!$B$16,9,1)))*'Custos Fixos'!$G$3:$G$100) | K9: =SUMPRODUCT(('Custos Fixos'!$E$3:$E$100<EDATE(DATE(Configurações!$B$16,10,1),1))*(('Custos Fixos'!$F$3:$F$100="")+('Custos Fixos'!$F$3:$F$100>=DATE(Configurações!$B$16,10,1)))*'Custos Fixos'!$G$3:$G$100) | L9: =SUMPRODUCT(('Custos Fixos'!$E$3:$E$100<EDATE(DATE(Configurações!$B$16,11,1),1))*(('Custos Fixos'!$F$3:$F$100="")+('Custos Fixos'!$F$3:$F$100>=DATE(Configurações!$B$16,11,1)))*'Custos Fixos'!$G$3:$G$100) | M9: =SUMPRODUCT(('Custos Fixos'!$E$3:$E$100<EDATE(DATE(Configurações!$B$16,12,1),1))*(('Custos Fixos'!$F$3:$F$100="")+('Custos Fixos'!$F$3:$F$100>=DATE(Configurações!$B$16,12,1)))*'Custos Fixos'!$G$3:$G$100) | N9: =SUM(B9:M9)
A10: Gastos adicionais | B10: =SUMIFS('Gastos Adicionais'!$D:$D,'Gastos Adicionais'!$A:$A,">="&DATE(Configurações!$B$16,1,1),'Gastos Adicionais'!$A:$A,"<"&EDATE(DATE(Configurações!$B$16,1,1),1)) | C10: =SUMIFS('Gastos Adicionais'!$D:$D,'Gastos Adicionais'!$A:$A,">="&DATE(Configurações!$B$16,2,1),'Gastos Adicionais'!$A:$A,"<"&EDATE(DATE(Configurações!$B$16,2,1),1)) | D10: =SUMIFS('Gastos Adicionais'!$D:$D,'Gastos Adicionais'!$A:$A,">="&DATE(Configurações!$B$16,3,1),'Gastos Adicionais'!$A:$A,"<"&EDATE(DATE(Configurações!$B$16,3,1),1)) | E10: =SUMIFS('Gastos Adicionais'!$D:$D,'Gastos Adicionais'!$A:$A,">="&DATE(Configurações!$B$16,4,1),'Gastos Adicionais'!$A:$A,"<"&EDATE(DATE(Configurações!$B$16,4,1),1)) | F10: =SUMIFS('Gastos Adicionais'!$D:$D,'Gastos Adicionais'!$A:$A,">="&DATE(Configurações!$B$16,5,1),'Gastos Adicionais'!$A:$A,"<"&EDATE(DATE(Configurações!$B$16,5,1),1)) | G10: =SUMIFS('Gastos Adicionais'!$D:$D,'Gastos Adicionais'!$A:$A,">="&DATE(Configurações!$B$16,6,1),'Gastos Adicionais'!$A:$A,"<"&EDATE(DATE(Configurações!$B$16,6,1),1)) | H10: =SUMIFS('Gastos Adicionais'!$D:$D,'Gastos Adicionais'!$A:$A,">="&DATE(Configurações!$B$16,7,1),'Gastos Adicionais'!$A:$A,"<"&EDATE(DATE(Configurações!$B$16,7,1),1)) | I10: =SUMIFS('Gastos Adicionais'!$D:$D,'Gastos Adicionais'!$A:$A,">="&DATE(Configurações!$B$16,8,1),'Gastos Adicionais'!$A:$A,"<"&EDATE(DATE(Configurações!$B$16,8,1),1)) | J10: =SUMIFS('Gastos Adicionais'!$D:$D,'Gastos Adicionais'!$A:$A,">="&DATE(Configurações!$B$16,9,1),'Gastos Adicionais'!$A:$A,"<"&EDATE(DATE(Configurações!$B$16,9,1),1)) | K10: =SUMIFS('Gastos Adicionais'!$D:$D,'Gastos Adicionais'!$A:$A,">="&DATE(Configurações!$B$16,10,1),'Gastos Adicionais'!$A:$A,"<"&EDATE(DATE(Configurações!$B$16,10,1),1)) | L10: =SUMIFS('Gastos Adicionais'!$D:$D,'Gastos Adicionais'!$A:$A,">="&DATE(Configurações!$B$16,11,1),'Gastos Adicionais'!$A:$A,"<"&EDATE(DATE(Configurações!$B$16,11,1),1)) | M10: =SUMIFS('Gastos Adicionais'!$D:$D,'Gastos Adicionais'!$A:$A,">="&DATE(Configurações!$B$16,12,1),'Gastos Adicionais'!$A:$A,"<"&EDATE(DATE(Configurações!$B$16,12,1),1)) | N10: =SUM(B10:M10)
A11: Lucro líquido | B11: =B7-B8-B9-B10 | C11: =C7-C8-C9-C10 | D11: =D7-D8-D9-D10 | E11: =E7-E8-E9-E10 | F11: =F7-F8-F9-F10 | G11: =G7-G8-G9-G10 | H11: =H7-H8-H9-H10 | I11: =I7-I8-I9-I10 | ... M11: =M7-M8-M9-M10 | N11: =SUM(B11:M11)

Sheet Dashboard
B2: 📊 Dashboard financeiro
B3: Let's Go · confidencial · caixa exige registo das saídas efetivamente pagas
B5: Faturação total | E5: Margem bruta | H5: Lucro previsto (faturado)
B6: ='Rendimentos e Lucros'!$N$5 | E6: ='Rendimentos e Lucros'!$N$7 | H6: ='Rendimentos e Lucros'!$N$11
B8: Resultado de caixa registado | E8: A receber | H8: Já recebido
B9: =Configurações!$B$18+SUM('Importar Registos'!$C:$C)-SUM('Saídas de Caixa'!$E:$E) | E9: =SUMIFS('Importar Reservas'!$W:$W,'Importar Reservas'!$W:$W,">0") | H9: =SUM('Importar Registos'!$C:$C)
B11: Comissões a pagar | E11: Custos fixos (mês) | H11: Gastos adicionais
B12: =SUM(Comissões!$H:$H) | E12: ='Custos Fixos'!$G$10 | H12: =SUM('Gastos Adicionais'!$D:$D)
B14: Saldo de caixa | E14: Nº de reservas | H14: Nº de clientes
B15: =Configurações!$B$18+SUM('Importar Registos'!$C:$C)-SUM('Saídas de Caixa'!$E:$E) | E15: =COUNTA('Importar Reservas'!$A$3:$A$2000) | H15: =COUNTUNIQUE(FILTER('Importar Reservas'!$D$3:$D$2000,'Importar Reservas'!$D$3:$D$2000<>""))
B17: Ticket médio / cliente | E17: Ticket médio / reserva | H17: Receita do último mês
B18: =IFERROR('Rendimentos e Lucros'!$N$5/H15,0) | E18: =IFERROR('Rendimentos e Lucros'!$N$5/E15,0) | H18: =SUMIFS('Importar Reservas'!$O:$O,'Importar Reservas'!$B:$B,">="&EOMONTH(TODAY(),-1)+1,'Importar Reservas'!$B:$B,"<="&EOMONTH(TODAY(),0))
B20: Variação vs mês anterior
B21: =IFERROR((SUMIFS('Importar Reservas'!$O:$O,'Importar Reservas'!$B:$B,">="&EOMONTH(TODAY(),-1)+1,'Importar Reservas'!$B:$B,"<="&EOMONTH(TODAY(),0))-SUMIFS('Importar Reservas'!$O:$O,'Importar Reservas'!$B:$B,">="&EOMONTH(TODAY(),-2)+1,'Importar Reservas'!$B:$B,"<="&EOMONTH(TODAY(),-1)))/SUMIFS('Importar Reservas'!$O:$O,'Importar Reservas'!$B:$B,">="&EOMONTH(TODAY(),-2)+1,'Importar Reservas'!$B:$B,"<="&EOMONTH(TODAY(),-1)),0)
B24: Destaques
B25: Pacote mais vendido | D25: =IFERROR(INDEX($L$40:$L$44,MATCH(MAX($M$40:$M$44),$M$40:$M$44,0)),"")
B26: Destino mais vendido | D26: =IFERROR(INDEX($O$40:$O$44,MATCH(MAX($P$40:$P$44),$P$40:$P$44,0)),"")
L40: Réveillon Madeira 2026 | M40: =COUNTIF('Importar Reservas'!$F$3:$F$42,$L40) | O40: Funchal, Madeira | P40: =COUNTIF('Importar Reservas'!$H$3:$H$42,$O40)
L41: Peregrinação a Fátima | M41: =COUNTIF('Importar Reservas'!$F$3:$F$42,$L41) | O41: Fátima | P41: =COUNTIF('Importar Reservas'!$H$3:$H$42,$O41)
L42: Lua de Mel Maldivas | M42: =COUNTIF('Importar Reservas'!$F$3:$F$42,$L42) | O42: Maldivas | P42: =COUNTIF('Importar Reservas'!$H$3:$H$42,$O42)
L43: City Break Roma | M43: =COUNTIF('Importar Reservas'!$F$3:$F$42,$L43) | O43: Roma, Itália | P43: =COUNTIF('Importar Reservas'!$H$3:$H$42,$O43)
L44: Safari Tanzânia | M44: =COUNTIF('Importar Reservas'!$F$3:$F$42,$L44) | O44: Tanzânia | P44: =COUNTIF('Importar Reservas'!$H$3:$H$42,$O44)
L46: Receita | M46: ='Rendimentos e Lucros'!$N$5
L47: Custo | M47: ='Rendimentos e Lucros'!$N$6
L48: Margem | M48: ='Rendimentos e Lucros'!$N$7
L49: Lucro | M49: ='Rendimentos e Lucros'!$N$11
L52: Instalações | M52: =SUMIF('Custos Fixos'!$B:$B,$L52,'Custos Fixos'!$G:$G)
L53: Salários | M53: =SUMIF('Custos Fixos'!$B:$B,$L53,'Custos Fixos'!$G:$G)
L54: Software | M54: =SUMIF('Custos Fixos'!$B:$B,$L54,'Custos Fixos'!$G:$G)
L55: Serviços | M55: =SUMIF('Custos Fixos'!$B:$B,$L55,'Custos Fixos'!$G:$G)

Sheet Importar Registos
